Workbook
Name Beg_Bal_2: #REF!
Name End_Bal_2: #REF!
Name Extra_Pay_2: #REF!
Name Int_2: #REF!
Name Interest_Rate_2: #REF!
Name Loan_Amount_2: #REF!
Name Loan_Start_2: #REF!
Name Loan_Years_2: #REF!
Name Num_Pmt_Per_Year_2: #REF!
Name Pay_Num_2: #REF!
Name Princ_2: #REF!
Name Sched_Pay_2: #REF!
Name Scheduled_Extra_Payments_2: #REF!
Name Scheduled_Monthly_Payment_2: #REF!
Name Total_Pay_2: #REF!

Sheet Sheet1
A1: Here is the percentage of total household investables ($1,118,616) for each individual asset/fund, based on the target weights and current account balances you provided.
A2: Total Household Investables: $1,118,616 (Crypto + M1 + TSP + Cleveland Clinic 403(b))
A3: Crypto Assets (Total Crypto: $16,700 → 1.49% of household)
A4: BTC: $6,680 → 0.60%
A5: ETH: $3,340 → 0.30%
A6: SOL: $1,670 → 0.15%
A7: BNB: $1,002 → 0.09%
A8: LINK: $1,002 → 0.09%
A9: TAO: $835 → 0.07%
A10: HYPE: $835 → 0.07%
A11: XRP: $501 → 0.04%
A12: TRX: $501 → 0.04%
... A34: Crypto (all 10 assets combined): $16,700 → ~1.5%

Sheet Share Count
A1: Account | B1: Fund / Asset | C1: Shares Owned
A2: TSP Civilian | B2: C Fund | C2: 1996.7504
A3: TSP Civilian | B3: S Fund | C3: 961.81153
A4: TSP Civilian | B4: I Fund | C4: 1367.9801
A5: TSP Uniformed | B5: C Fund | C5: 464.38822
A6: TSP Uniformed | B6: S Fund | C6: 738.12773
A7: Fidelity 403b | B7: VIIIX | C7: 208.278
A8: Fidelity 403b | B8: VTPSX | C8: 1246.571
A9: Fidelity 403b | B9: VEMPX | C9: 141.737
A10: Fidelity 401a | B10: VTPSX | C10: 701.836
A11: M1 Finance | B11: VTI | C11: 51.69695
A12: M1 Finance | B12: QQQM | C12: 33.09859
A13: M1 Finance | B13: AVUV | C13: 238.65392
... A27: Regan Investment | B27: AVES | C27: 20.74981

Sheet Net Worth
A1: Liquid Cash | E1: Total Assets | F1: =SUM($B$7,$B$19,$B$26,$B$31,$B$40) -> 1785117.2 | K1: Proposed | L1: Current | N1: Crypto Deposit | O1: 28500 | Q1: 0.15
A2: Cash On Hand | B2: ='Checking Transaction Log'!G2 -> 180 | C2: =TODAY() -> 46324 | E2: Total Liabilities | F2: =F14 -> 169226.55 | J2: Stocks | K2: 0.75 | L2: =K5/(K5+K6) -> 0.8016265 | N2: Crypto Profit | O2: =B12-O1 -> -4875 | Q2: 1 yr | R2: =E20*(1+$Q$1) -> 1858274.3
A3: PayPal | B3: 0 | C3: =TODAY() -> 46324 | E3: Net Worth | F3: =F1-F2 -> 1615890.7 | J3: Crypto | K3: 0.25 | L3: =K6/(K5+K6) -> 0.1983735 | N3: M1 Deposit | O3: 67870.08 | Q3: 2 yr | R3: =R2*(1+$Q$1) -> 2137015.4
A4: Huntington Checking | B4: 0 | C4: =TODAY() -> 46324 | N4: M1 Profit | O4: =B10-O3 -> 27598.45 | Q4: 3 yr | R4: =R3*(1+$Q$1) -> 2457567.7
A5: PNC Checking | B5: ='Checking Transaction Log'!G1 -> 7573.13 | C5: =TODAY() -> 46324 | E5: Liabilities | J5: M1 Finance | K5: =B10 -> 95468.53 | L5: =K5/F3 -> 0.059081058 | N5: DFS Deposit | Q5: 4 yr | R5: =R4*(1+$Q$1) -> 2826202.9
A6: PNC Savings | B6: ='Savings Transaction Log'!A3 -> 23930.53 | C6: =TODAY() -> 46324 | E6: Rocket Mortgage | F6: 134615.22 | G6: 46310 | J6: Kraken | K6: =B12 -> 23625 | L6: =K6/F3 -> 0.01462042 | N6: DFS Profit | Q6: 5 yr | R6: =R5*(1+$Q$1) -> 3250133.3
A7: Total Liquid Cash | B7: =SUM(B2:B6) -> 31683.66 | C7: =B7/F3 -> 0.019607552 | E7: Lormet - RAV4 | F7: 16806 | G7: 46310 | J7: New Deposit | K7: =IF((B3+B4+B6)>10000,(B3+B4+B6-10000),0) -> 13930.53 | N7: Total Deposit | O7: =O1+O3+O5 -> 96370.08 | Q7: 6 yr | R7: =R6*(1+$Q$1) -> 3737653.3
E8: GM Financial (1 payment left) | F8: 0 | G8: 46310 | J8: Total | K8: =SUM(K5:K7) -> 133024.06 | L8: =K8/F3 -> 0.082322438 | N8: Total Profit | O8: =O2+O4+O6 -> 22723.45 | Q8: 7 yr | R8: =R7*(1+$Q$1) -> 4298301.3
A9: Savings Investments | E9: Wells Fargo - Pool (Aug 11, 2030) | F9: 8840 | G9: 46310 | K9: Deposit | L9: Total | Q9: 8 yr | R9: =R8*(1+$Q$1) -> 4943046.5
A10: Isaac - M1 | B10: 95468.53 | C10: 46312 | E10: Wells Fargo - Deck (Feb 3, 2028) | F10: 8965.33 | G10: 46310 | J10: M1 Finance | K10: =(K8*K2)-K5 -> 4299.515 | L10: =K10+K5 -> 99768.045 | Q10: 9 yr | R10: =R9*(1+$Q$1) -> 5684503.5
A11: Regan-M1 | B11: 13417.66 | C11: 46312 | E11: Lowes - Aug 14, 2026 | F11: 0 | G11: 46310 | J11: BinanceUS | K11: =(K8*K3)-K6 -> 9631.015 | L11: =K11+K6 -> 33256.015 | N11: 12/31 Crypto Bal | O11: 5258.27 | Q11: 10 yr | R11: =R10*(1+$Q$1) -> 6537179
A12: Crypto - Kraken | B12: 23625 | C12: 46312 | E12: Lowes - Dec 15, 2026 | F12: 0 | G12: 46310 | L12: =L11/F3 -> 0.02058061 | N12: 2023 Crypto Deposit | O12: 6000
E13: Lowes - Mar 2027 | F13: 0 | G13: 46310 | N13: 2023 Crypto Withdraw | O13: 0
E14: Total Liabilities | F14: =SUM(F6:F13) -> 169226.55 | N14: Current Crypto Bal | O14: =B18 -> 0
J15: Stocks | K15: =SUM(B10:B11) -> 108886.19 | L15: =K15/F3 -> 0.067384627 | N15: 2023 Crypto Return | O15: =O14-O11-O12 -> -11258.27
E16: Available Cash | F16: =SUM(B7,B10,B18,B13,B12,B17,B15,B16,B14) -> 150777.19 | J16: Crypto | K16: =B12 -> 23625 | L16: =K16/F3 -> 0.01462042
J17: DFS | K17: =SUM(B13) -> 0 | L17: =K17/F3 -> 0
N18: Total Invested | O18: =B19+B26+B31-F6 -> 1532118.3
A19: Total Savings Investments | B19: =SUM(B10:B18) -> 132511.19 | C19: =B19/F3 -> 0.082005047 | E19: Current Net Worth | F19: 2026 Current Gain | G19: 2026 Current Gain | N19: C Fund - US Large Cap | O19: =($B$22+$B$23)*0.5 -> 288756.31 | P19: =O19/$O$18 -> 0.18846867 | Q19: TSP
E20: =F3 -> 1615890.7 | F20: =E20-E22 -> 200888.24 | G20: =(E20-E22)/E22 -> 0.14197024 | J20: Goal | K20: Distance | N20: VIIIX - US Large Cap | O20: =($B$24+$B$25)*0.5 -> 268354.88 | P20: =O20/$O$18 -> 0.17515284 | Q20: Clinic
A21: Retirement Investments | E21: 46023 | F21: 2026 Projected | G21: 2026 Projected Gain | J21: 2000000 | K21: =1-($E$20/J21) -> 0.19205467 | N21: VOO - US Large Cap | O21: =($B$10+$B$11)*0.25 -> 27221.548 | P21: =O21/$O$18 -> 0.017767262 | Q21: M1
A22: TSP Civilian | B22: =-'TSP-401K'!H84 -> 439148.43 | C22: 46312 | E22: 1415002.4 | F22: =((F20/(C2-E21))*365)+E22 -> 1658604.4 | G22: =(F22-E22)/E22 -> 0.17215661 | J22: 3000000 | K22: =1-($E$20/J22) -> 0.46136978 | N22: I Fund - International | O22: =($B$22+$B$23)*0.3 -> 173253.79 | P22: =O22/$O$18 -> 0.1130812 | Q22: TSP
A23: TSP Uniformed Service | B23: =-'TSP-401K'!L84 -> 138364.19 | C23: =C22 -> 46312 | J23: 4000000 | K23: =1-($E$20/J23) -> 0.59602733 | N23: VTPSX - International | O23: =($B$24+$B$25)*0.3 -> 161012.92 | P23: =O23/$O$18 -> 0.1050917 | Q23: Clinic
A24: Cleveland Clinic 403b | B24: =-'TSP-401K'!Q84 -> 411046.01 | C24: =C22 -> 46312 | E24: Asset Type | F24: Net Worth Balance | G24: Net Worth Pct | J24: 5000000 | K24: =1-($E$20/J24) -> 0.67682187 | N24: VEA - International | O24: =($B$10+$B$11)*0.25 -> 27221.548 | P24: =O24/$O$18 -> 0.017767262 | Q24: M1
A25: Cleveland Clinic 401a | B25: =-'TSP-401K'!V84 -> 125663.74 | C25: =C22 -> 46312 | E25: Liquid Cash | F25: =B7 -> 31683.66 | G25: =F25/SUM($F$25:$F$31) -> 0.019393853 | N25: VWO - International | O25: =($B$10+$B$11)*0.25 -> 27221.548 | P25: =O25/$O$18 -> 0.017767262 | Q25: M1
A26: Total Retirement Investments | B26: =SUM(B22:B25) -> 1114222.4 | C26: =B26/F3 -> 0.68954069 | E26: Kids Savings | F26: =(B11) -> 13417.66 | G26: =F26/SUM($F$25:$F$31) -> 0.0082130702 | N26: S Fund - US Small/Mid Cap | O26: =($B$22+$B$23)*0.2 -> 115502.52 | P26: =O26/$O$18 -> 0.075387469 | Q26: TSP
E27: Stock Investments | F27: =B10 -> 95468.53 | G27: =F27/SUM($F$25:$F$31) -> 0.058437145 | N27: VEMPX - US Small/Mid Cap | O27: =($B$24+$B$25)*0.2 -> 107341.95 | P27: =O27/$O$18 -> 0.070061135 | Q27: Clinic
A28: Real Estate | E28: Crypto Investments | F28: =B12 -> 23625 | G28: =F28/SUM($F$25:$F$31) -> 0.014461075 | N28: IVOV - US Small/Mid Cap | O28: =($B$10+$B$11)*0.1 -> 10888.619 | P28: =O28/$O$18 -> 0.0071069047 | Q28: M1
A29: Main Home - Redfin | B29: 315000 | C29: 46305 | E29: Retirement Investments | F29: =B26 -> 1114222.4 | G29: =F29/SUM($F$25:$F$31) -> 0.68202552 | N29: VIOV - US Small/Mid Cap | O29: =($B$10+$B$11)*0.1 -> 10888.619 | P29: =O29/$O$18 -> 0.0071069047 | Q29: M1
A30: Rental Property - Redfin | B30: 105000 | C30: 46305 | E30: Real Estate | F30: =B31-F6 -> 285384.78 | G30: =F30/SUM($F$25:$F$31) -> 0.17468659 | N30: Real Estate | O30: =B31-F6 -> 285384.78 | P30: =O30/$O$18 -> 0.18626811 | Q30: Real
A31: Total Property Values | B31: =SUM(B29:B30) -> 420000 | C31: =(B31-F6)/F3 -> 0.17661144 | E31: Vehicles | F31: =B40-F8-F7 -> 69894 | G31: =F31/SUM($F$25:$F$31) -> 0.042782745 | N31: VNQ - US REIT | O31: =($B$10+$B$11)*0.05 -> 5444.3095 | P31: =O31/$O$18 -> 0.0035534523 | Q31: M1
N32: Crypto | O32: =B12 -> 23625 | P32: =O32/$O$18 -> 0.015419827 | Q32: Kraken
A33: Vehicles
A34: 2019 Chevy Silverado (JAF3923) | B34: 21500 | C34: 46305
A35: 2019 Toyota Rav 4 (JZJ5569) | B35: 20500 | C35: 46305 | N35: US Large Cap | O35: =SUM(O19:O21) -> 584332.73 | P35: =O35/$O$18 -> 0.38138877
A36: 2013 Toyota Corolla (KLM2660) | B36: 9000 | C36: 46305 | N36: International | O36: =SUM(O22:O25) -> 388709.81 | P36: =O36/$O$18 -> 0.25370743
A37: 2003 Toyota Corolla | B37: 2700 | C37: 46305 | N37: US Small/Mid Cap | O37: =SUM(O26:O29) -> 244621.71 | P37: =O37/$O$18 -> 0.15966241
A38: 2005 Gulf Stream Sun Voyager (HEH3760) | B38: 23000 | C38: 46305 | N38: Real Estate | O38: =O30+O31 -> 290829.09 | P38: =O38/$O$18 -> 0.18982156
A39: Custom EZGO TXT | B39: 10000 | C39: 46305 | N39: Crypto | O39: =O32 -> 23625 | P39: =O39/$O$18 -> 0.015419827
A40: Total Vehicle Values | B40: =SUM(B34:B39) -> 86700 | C40: =(B40-F8-F7)/F3 -> 0.043254164 | N40: Totals | O40: =SUM(O35:O39) -> 1532118.3 | P40: =SUM(P35:P39) -> 1
...

Sheet 50-30-20
B1: Proposed | D1: Actual | H1: Proposed | J1: Actual | N1: Proposed | P1: Actual | T1: Proposed | V1: Actual
A2: Income | B2: =SUM(B4:B7) -> 206163.2 | D2: =SUM(D4:D7) -> 169150.76 | G2: Needs | H2: =SUM(H4:H30) -> 88260 | I2: =H2/B2 -> 0.42810744 | J2: =SUM(J4:J30) -> 74465.425 | K2: =J2/D2 -> 0.4402311 | M2: Wants | N2: =SUM(N4:N19) -> 67740 | O2: =N2/B2 -> 0.32857464 | P2: =SUM(P4:P19) -> 65604.125 | Q2: =P2/D2 -> 0.3878441 | S2: Savings | T2: =SUM(T4:T7) -> 50163.202 | U2: =T2/B2 -> 0.24331792 | V2: =SUM(V4:V7) -> 29081.21 | W2: =V2/D2 -> 0.1719248
A4: Lorri Pay | B4: ='Proposed Budget'!N68 -> 110347.83 | C4: =B4/$B$2 -> 0.53524504 | D4: ='Monthly Breakdown'!E49 -> 87081.64 | E4: =D4/$D$2 -> 0.51481672 | G4: ='Proposed Budget'!C5 -> Groceries/Household | H4: ='Proposed Budget'!F5 -> 14400 | I4: =H4/$B$2 -> 0.069847576 | J4: ='Monthly Breakdown'!E5 -> 10679.77 | K4: =J4/$D$2 -> 0.063137582 | M4: ='Proposed Budget'!C6 -> Dining Out | N4: ='Proposed Budget'!F6 -> 14400 | O4: =N4/$B$2 -> 0.069847576 | P4: ='Monthly Breakdown'!E6 -> 10506.12 | Q4: =P4/$D$2 -> 0.062110983 | S4: ='Proposed Budget'!C46 -> Our Savings | T4: ='Proposed Budget'!F46 -> 49563.202 | U4: =T4/$B$2 -> 0.24040761 | V4: ='Monthly Breakdown'!E46 -> 42892.82 | W4: =V4/$D$2 -> 0.25357746
A5: Isaac Pay | B5: ='Proposed Budget'!N44 -> 71858.371 | C5: =B5/$B$2 -> 0.34855091 | D5: ='Monthly Breakdown'!E50 -> 61728.68 | E5: =D5/$D$2 -> 0.36493292 | G5: ='Proposed Budget'!C7 -> Misc Food | H5: ='Proposed Budget'!F7*0.5 -> 900 | I5: =H5/$B$2 -> 0.0043654735 | J5: ='Monthly Breakdown'!E7*0.5 -> 556.385 | K5: =J5/$D$2 -> 0.0032892847 | M5: ='Proposed Budget'!C7 -> Misc Food | N5: ='Proposed Budget'!F7*0.5 -> 900 | O5: =N5/$B$2 -> 0.0043654735 | P5: ='Monthly Breakdown'!E7*0.5 -> 556.385 | Q5: =P5/$D$2 -> 0.0032892847 | S5: ='Proposed Budget'!C45 -> Kids Savings | T5: ='Proposed Budget'!F45 -> 600 | U5: =T5/$B$2 -> 0.0029103157 | V5: ='Monthly Breakdown'!E45 -> 450 | W5: =V5/$D$2 -> 0.0026603487
A6: Isaac Guard | B6: ='Proposed Budget'!J21 -> 14357 | C6: =B6/$B$2 -> 0.069639004 | D6: ='Monthly Breakdown'!E51 -> 12340.44 | E6: =D6/$D$2 -> 0.072955274 | G6: ='Proposed Budget'!C8 -> Gasoline | H6: ='Proposed Budget'!F8 -> 7200 | I6: =H6/$B$2 -> 0.034923788 | J6: ='Monthly Breakdown'!E8 -> 6416.07 | K6: =J6/$D$2 -> 0.037931074 | M6: ='Proposed Budget'!C9 -> Family Entertainment | N6: ='Proposed Budget'!F9 -> 8400 | O6: =N6/$B$2 -> 0.04074442 | P6: ='Monthly Breakdown'!E9 -> 8009.17 | Q6: =P6/$D$2 -> 0.0473493 | S6: Monthly Difference | V6: ='Budget Breakdown'!T16 -> 5043.65 | W6: =V6/$D$2 -> 0.029817484
A7: Rental | B7: ='Proposed Budget'!J22 -> 9600 | C7: =B7/$B$2 -> 0.046565051 | D7: ='Monthly Breakdown'!E52 -> 8000 | E7: =D7/$D$2 -> 0.047295088 | G7: ='Proposed Budget'!C14 -> Rocket Mortgage | H7: ='Proposed Budget'!F14 -> 15420 | I7: =H7/$B$2 -> 0.074795113 | J7: ='Monthly Breakdown'!E14 -> 12516.2 | K7: =J7/$D$2 -> 0.073994347 | M7: ='Proposed Budget'!C10 -> Miscellaneous Spending | N7: ='Proposed Budget'!F10 -> 10800 | O7: =N7/$B$2 -> 0.052385682 | P7: ='Monthly Breakdown'!E10 -> 8495.71 | Q7: =P7/$D$2 -> 0.050225669 | S7: Variable Savings | V7: ='Savings Transaction Log'!I2+'Savings Transaction Log'!K2+'Savings Transaction Log'!M2+'Savings Transaction Log'!O2+'Savings Transaction Log'!Q2+'Savings Transaction Log'!S2+'Savings Transaction Log'!U2+'Savings Transaction Log'!W2+'Savings Transaction Log'!Y2+'Savings Transaction Log'!AA2+'Savings Transaction Log'!AC2 -> -19305.26 | W7: =V7/$D$2 -> -0.1141305
G8: ='Proposed Budget'!C15 -> EH Roberts | H8: ='Proposed Budget'!F15 -> 240 | I8: =H8/$B$2 -> 0.0011641263 | J8: ='Monthly Breakdown'!E15 -> 161.1 | K8: =J8/$D$2 -> 0.00095240483 | M8: ='Proposed Budget'!C11 -> Department Stores/Clothes | N8: ='Proposed Budget'!F11 -> 4200 | O8: =N8/$B$2 -> 0.02037221 | P8: ='Monthly Breakdown'!E11 -> 2911.15 | Q8: =P8/$D$2 -> 0.017210387
G9: ='Proposed Budget'!C16 -> Verizon Wireless | H9: ='Proposed Budget'!F16 -> 3240 | I9: =H9/$B$2 -> 0.015715705 | J9: ='Monthly Breakdown'!E16 -> 2847.28 | K9: =J9/$D$2 -> 0.016832795 | M9: ='Proposed Budget'!C12 -> Alcohol/Bars | N9: ='Proposed Budget'!F12 -> 8400 | O9: =N9/$B$2 -> 0.04074442 | P9: ='Monthly Breakdown'!E12 -> 7347.57 | Q9: =P9/$D$2 -> 0.043437996
G10: ='Proposed Budget'!C17 -> Spectrum TV/Internet | H10: ='Proposed Budget'!F17*0.5 -> 1230 | I10: =H10/$B$2 -> 0.0059661471 | J10: ='Monthly Breakdown'!E17*0.5 -> 1037.955 | K10: =J10/$D$2 -> 0.0061362716 | M10: ='Proposed Budget'!C17 -> Spectrum TV/Internet | N10: ='Proposed Budget'!F17*0.5 -> 1230 | O10: =N10/$B$2 -> 0.0059661471 | P10: ='Monthly Breakdown'!E17*0.5 -> 1037.955 | Q10: =P10/$D$2 -> 0.0061362716
G11: ='Proposed Budget'!C18 -> First Energy | H11: ='Proposed Budget'!F18 -> 2160 | I11: =H11/$B$2 -> 0.010477136 | J11: ='Monthly Breakdown'!E18 -> 2065.97 | K11: =J11/$D$2 -> 0.012213779 | M11: ='Proposed Budget'!C22 -> Planet Fitness | N11: ='Proposed Budget'!F22 -> 1740 | O11: =N11/$B$2 -> 0.0084399155 | P11: ='Monthly Breakdown'!E22 -> 1639.08 | Q11: =P11/$D$2 -> 0.009690054
G12: ='Proposed Budget'!C19 -> Vivint Home Security | H12: ='Proposed Budget'!F19 -> 1680 | I12: =H12/$B$2 -> 0.0081488839 | J12: ='Monthly Breakdown'!E19 -> 1366.8 | K12: =J12/$D$2 -> 0.0080803657 | M12: ='Proposed Budget'!C23 -> Lowes Rewards | N12: ='Proposed Budget'!F23*0.5 -> 2400 | O12: =N12/$B$2 -> 0.011641263 | P12: ='Monthly Breakdown'!E23*0.5 -> 1000 | Q12: =P12/$D$2 -> 0.0059118859
G13: ='Proposed Budget'!C20 -> Columbia Gas | H13: ='Proposed Budget'!F20 -> 1200 | I13: =H13/$B$2 -> 0.0058206314 | J13: ='Monthly Breakdown'!E20 -> 1071.36 | K13: =J13/$D$2 -> 0.0063337581 | M13: ='Proposed Budget'!C24 -> Wells Fargo - Pool | N13: ='Proposed Budget'!F24 -> 2400 | O13: =N13/$B$2 -> 0.011641263 | P13: ='Monthly Breakdown'!E24 -> 2000 | Q13: =P13/$D$2 -> 0.011823772
G14: ='Proposed Budget'!C21 -> Medical Bills | H14: ='Proposed Budget'!F21 -> 0 | I14: =H14/$B$2 -> 0 | J14: ='Monthly Breakdown'!E21 -> 1898.15 | K14: =J14/$D$2 -> 0.011221646 | M14: ='Proposed Budget'!C25 -> Wells Fargo - Deck | N14: ='Proposed Budget'!F25*0.5 -> 3600 | O14: =N14/$B$2 -> 0.017461894 | P14: ='Monthly Breakdown'!E25*0.5 -> 1800 | Q14: =P14/$D$2 -> 0.010641395
G15: ='Proposed Budget'!C23 -> Lowes Rewards | H15: ='Proposed Budget'!F23*0.5 -> 2400 | I15: =H15/$B$2 -> 0.011641263 | J15: ='Monthly Breakdown'!E23*0.5 -> 1000 | K15: =J15/$D$2 -> 0.0059118859 | M15: ='Proposed Budget'!C26 -> Massage Envy | N15: ='Proposed Budget'!F26 -> 1020 | O15: =N15/$B$2 -> 0.0049475367 | P15: ='Monthly Breakdown'!E26 -> 934.73 | Q15: =P15/$D$2 -> 0.0055260171
G16: ='Proposed Budget'!C25 -> Wells Fargo - Deck | H16: ='Proposed Budget'!F25*0.5 -> 3600 | I16: =H16/$B$2 -> 0.017461894 | J16: ='Monthly Breakdown'!E25*0.5 -> 1800 | K16: =J16/$D$2 -> 0.010641395 | M16: ='Proposed Budget'!C27 -> Streaming/Music | N16: ='Proposed Budget'!F27 -> 1200 | O16: =N16/$B$2 -> 0.0058206314 | P16: ='Monthly Breakdown'!E27 -> 1390.11 | Q16: =P16/$D$2 -> 0.0082181718
G17: ='Proposed Budget'!C28 -> GM Financial/Toyota | H17: ='Proposed Budget'!F28 -> 14400 | I17: =H17/$B$2 -> 0.069847576 | J17: ='Monthly Breakdown'!E28 -> 9148.86 | K17: =J17/$D$2 -> 0.054087017 | M17: ='Proposed Budget'!C38 -> Camping/Vacation | N17: ='Proposed Budget'!F38 -> 4800 | O17: =N17/$B$2 -> 0.023282525 | P17: ='Savings Transaction Log'!R5 -> 6641.09 | Q17: =P17/$D$2 -> 0.039261367
G18: ='Proposed Budget'!C29 -> Ohio Turnpike | H18: ='Proposed Budget'!F29 -> 1440 | I18: =H18/$B$2 -> 0.0069847576 | J18: ='Monthly Breakdown'!E29 -> 1022.5 | K18: =J18/$D$2 -> 0.0060449034 | M18: ='Proposed Budget'!C39 -> Home Maintenance | N18: ='Proposed Budget'!F39*0.5 -> 2250 | O18: =N18/$B$2 -> 0.010913684 | P18: ='Savings Transaction Log'!T5*0.5 -> 11335.055 | Q18: =P18/$D$2 -> 0.067011552
G19: ='Proposed Budget'!C30 -> Water Bill - Main | H19: ='Proposed Budget'!F30 -> 900 | I19: =H19/$B$2 -> 0.0043654735 | J19: ='Monthly Breakdown'!E30 -> 912.12 | K19: =J19/$D$2 -> 0.0053923494
G20: ='Proposed Budget'!C31 -> Water Bill - Rental | H20: ='Proposed Budget'!F31 -> 900 | I20: =H20/$B$2 -> 0.0043654735 | J20: ='Monthly Breakdown'!E31 -> 635.79 | K20: =J20/$D$2 -> 0.003758718
G21: ='Proposed Budget'!C33 -> Vehicle Maintenance | H21: ='Proposed Budget'!F33 -> 4200 | I21: =H21/$B$2 -> 0.02037221 | J21: ='Savings Transaction Log'!H5 -> 1616.64 | K21: =J21/$D$2 -> 0.0095573913
G22: ='Proposed Budget'!C34 -> Car Insurance | H22: ='Proposed Budget'!F34 -> 3840 | I22: =H22/$B$2 -> 0.01862602 | J22: ='Savings Transaction Log'!J5 -> 2159 | K22: =J22/$D$2 -> 0.012763762
G23: ='Proposed Budget'!C35 -> Rental Garbage | H23: ='Proposed Budget'!F35 -> 300 | I23: =H23/$B$2 -> 0.0014551578 | J23: ='Savings Transaction Log'!L5 -> 260.79 | K23: =J23/$D$2 -> 0.0015417607
G24: ='Proposed Budget'!C36 -> Garbage | H24: ='Proposed Budget'!F36 -> 300 | I24: =H24/$B$2 -> 0.0014551578 | J24: ='Savings Transaction Log'!N5 -> 260.79 | K24: =J24/$D$2 -> 0.0015417607
G25: ='Proposed Budget'!C37 -> Sanitation - Main | H25: ='Proposed Budget'!F37 -> 540 | I25: =H25/$B$2 -> 0.0026192841 | J25: ='Savings Transaction Log'!P5 -> 374.28 | K25: =J25/$D$2 -> 0.0022127007
G26: ='Proposed Budget'!C39 -> Home Maintenance | H26: ='Proposed Budget'!F39*0.5 -> 2250 | I26: =H26/$B$2 -> 0.010913684 | J26: ='Savings Transaction Log'!T5*0.5 -> 11335.055 | K26: =J26/$D$2 -> 0.067011552
G27: ='Proposed Budget'!C40 -> Rental Repairs | H27: ='Proposed Budget'!F40 -> 1200 | I27: =H27/$B$2 -> 0.0058206314 | J27: ='Savings Transaction Log'!V5 -> 0 | K27: =J27/$D$2 -> 0
G28: ='Proposed Budget'!C41 -> Rental Insurance | H28: ='Proposed Budget'!F41 -> 1020 | I28: =H28/$B$2 -> 0.0049475367 | J28: ='Savings Transaction Log'!X5 -> 500.5 | K28: =J28/$D$2 -> 0.0029588989
G29: ='Proposed Budget'!C42 -> Rental Property Taxes | H29: ='Proposed Budget'!F42 -> 2760 | I29: =H29/$B$2 -> 0.013387452 | J29: ='Savings Transaction Log'!Z5 -> 2447.78 | K29: =J29/$D$2 -> 0.014470996
G30: ='Proposed Budget'!C43 -> Rental Sanitation | H30: ='Proposed Budget'!F43 -> 540 | I30: =H30/$B$2 -> 0.0026192841 | J30: ='Savings Transaction Log'!AB5 -> 374.28 | K30: =J30/$D$2 -> 0.0022127007

Sheet Proposed Budget
A1: 2026 PROPOSED BUDGET
D2: MONTHLY | E2: % | F2: ANNUAL | G2: WEEKLY | J2: ANNUAL | K2: % | L2: MONTHLY
C3: TOTALS | D3: =SUM(D5:D61) -> 17180.267 | E3: =SUM(E5:E61) -> 1 | F3: =SUM(F5:F61) -> 206163.2 | G3: =F3/52 -> 3964.677 | I3: Gross Pay | J3: =L29+L49 -> 276499.57 | L3: =J3/12 -> 23041.631
A5: D | B5: 1 | C5: Groceries/Household | D5: 1200 | E5: =D5/$O$24 -> 0.069847576 | F5: =D5*12 -> 14400 | G5: =F5/52 -> 276.92308 | I5: Health/Life Insurance | J5: =L31+L53+L54+L55 -> 4120.9 | K5: =J5/J3 -> 0.014903821 | L5: =J5/12 -> 343.40833
A6: D | B6: 2 | C6: Dining Out | D6: 1200 | E6: =D6/$O$24 -> 0.069847576 | F6: =D6*12 -> 14400 | G6: =F6/52 -> 276.92308 | I6: Retirement | J6: =L32+L56 -> 17269.978 | K6: =J6/J3 -> 0.06245933 | L6: =J6/12 -> 1439.1648
A7: D | B7: 3 | C7: Misc Food | D7: 150 | E7: =D7/$O$24 -> 0.008730947 | F7: =D7*12 -> 1800 | G7: =F7/52 -> 34.615385 | I7: Pre-Tax Deductions | J7: =SUM(J5:J6) -> 21390.878 | K7: =J7/J3 -> 0.077363151 | L7: =SUM(L5:L6) -> 1782.5732
A8: D | B8: 4 | C8: Gasoline | D8: 600 | E8: =D8/$O$24 -> 0.034923788 | F8: =D8*12 -> 7200 | G8: =F8/52 -> 138.46154
A9: D | B9: 5 | C9: Family Entertainment | D9: 700 | E9: =D9/$O$24 -> 0.04074442 | F9: =D9*12 -> 8400 | G9: =F9/52 -> 161.53846 | I9: Taxable Pay | J9: =L35+L59 -> 255924.69 | L9: =J9/12 -> 21327.058
A10: D | B10: 6 | C10: Miscellaneous Spending | D10: 900 | E10: =D10/$O$24 -> 0.052385682 | F10: =D10*12 -> 10800 | G10: =F10/52 -> 207.69231
A11: D | B11: 7 | C11: Department Stores/Clothes | D11: 350 | E11: =D11/$O$24 -> 0.02037221 | F11: =D11*12 -> 4200 | G11: =F11/52 -> 80.769231 | I11: Federal Tax | J11: =L37+L61 -> 39427.36 | K11: =J11/J9 -> 0.15405845 | L11: =J11/12 -> 3285.6133
A12: D | B12: 8 | C12: Alcohol/Bars | D12: 700 | E12: =D12/$O$24 -> 0.04074442 | F12: =D12*12 -> 8400 | G12: =F12/52 -> 161.53846 | I12: Ohio Tax | J12: =L38+L62 -> 7415.6 | K12: =J12/J9 -> 0.028975711 | L12: =J12/12 -> 617.96667
I13: Medicare | J13: =L39+L63 -> 3961.2645 | K13: =J13/(J9+J6) -> 0.014499787 | L13: =J13/12 -> 330.10538
A14: F | B14: 9 | C14: Rocket Mortgage | D14: 1285 | E14: =D14/$O$24 -> 0.074795113 | F14: =D14*12 -> 15420 | G14: =F14/52 -> 296.53846 | I14: Social Security | J14: =L40+L64 -> 16938.028 | K14: =J14/(J9+J6) -> 0.061999847 | L14: =J14/12 -> 1411.5023
A15: F | B15: 10 | C15: EH Roberts | D15: 20 | E15: =D15/$O$24 -> 0.0011641263 | F15: =D15*12 -> 240 | G15: =F15/52 -> 4.6153846 | I15: FERS Retirement | J15: =L41 -> 833.9968 | K15: =J15/J3 -> 0.003016268 | L15: =J15/12 -> 69.499733
A16: F | B16: 11 | C16: Verizon Wireless | D16: 270 | E16: =D16/$O$24 -> 0.015715705 | F16: =D16*12 -> 3240 | G16: =F16/52 -> 62.307692 | I16: Cleveland Tax | J16: =L65 -> 4326.24 | K16: =J16/J9 -> 0.016904348 | L16: =J16/12 -> 360.52
A17: F | B17: 12 | C17: Spectrum TV/Internet | D17: 205 | E17: =D17/$O$24 -> 0.011932294 | F17: =D17*12 -> 2460 | G17: =F17/52 -> 47.307692 | I17: Employee Taxes | J17: =SUM(J11:J16) -> 72902.489 | K17: =J17/J3 -> 0.26366222 | L17: =SUM(L11:L16) -> 6075.2074
A18: F | B18: 13 | C18: First Energy | D18: 180 | E18: =D18/$O$24 -> 0.010477136 | F18: =D18*12 -> 2160 | G18: =F18/52 -> 41.538462
A19: F | B19: 14 | C19: Vivint Home Security | D19: 140 | E19: =D19/$O$24 -> 0.0081488839 | F19: =D19*12 -> 1680 | G19: =F19/52 -> 32.307692 | I19: Combined Take Home | J19: =L44+L68 -> 182206.2 | K19: =J19/J3 -> 0.65897463
A20: F | B20: 15 | C20: Columbia Gas | D20: 100 | E20: =D20/$O$24 -> 0.0058206314 | F20: =D20*12 -> 1200 | G20: =F20/52 -> 23.076923
A21: F | B21: 16 | C21: Medical Bills | D21: 0 | E21: =D21/$O$24 -> 0 | F21: =D21*12 -> 0 | G21: =F21/52 -> 0 | I21: Guard Take Home | J21: 14357 | L21: =J21/12 -> 1196.4167
A22: F | B22: 17 | C22: Planet Fitness | D22: 145 | E22: =D22/$O$24 -> 0.0084399155 | F22: =D22*12 -> 1740 | G22: =F22/52 -> 33.461538 | I22: Rental Income | J22: 9600 | L22: =J22/12 -> 800 | M22: =L22-D31-D35-D40-D41-D42-D43 -> 240 | N22: =M22*12 -> 2880
A23: F | B23: 18 | C23: Lowes Rewards | D23: 400 | E23: =D23/$O$24 -> 0.023282525 | F23: =D23*12 -> 4800 | G23: =F23/52 -> 92.307692
A24: F | B24: 19 | C24: Wells Fargo - Pool | D24: 200 | E24: =D24/$O$24 -> 0.011641263 | F24: =D24*12 -> 2400 | G24: =F24/52 -> 46.153846 | I24: Total Take Home | J24: =J19+J22+J21 -> 206163.2 | K24: =(J24+J6)/J3 -> 0.80807786 | L24: =J24/12 -> 17180.267 | N24: =J21+J22+N44+N68 -> 206163.2 | O24: =N24/12 -> 17180.267
A25: F | B25: 20 | C25: Wells Fargo - Deck | D25: 600 | E25: =D25/$O$24 -> 0.034923788 | F25: =D25*12 -> 7200 | G25: =F25/52 -> 138.46154
A26: F | B26: 21 | C26: Massage Envy | D26: 85 | E26: =D26/$O$24 -> 0.0049475367 | F26: =D26*12 -> 1020 | G26: =F26/52 -> 19.615385
A27: F | B27: 22 | C27: Streaming/Music | D27: 100 | E27: =D27/$O$24 -> 0.0058206314 | F27: =D27*12 -> 1200 | G27: =F27/52 -> 23.076923 | I27: ISAAC | J27: 50.12
A28: F | B28: 23 | C28: GM Financial/Toyota | D28: 1200 | E28: =D28/$O$24 -> 0.069847576 | F28: =D28*12 -> 14400 | G28: =F28/52 -> 276.92308 | J28: PAY PERIOD | K28: % | L28: ANNUAL | M28: MONTHLY
A29: F | B29: 24 | C29: Ohio Turnpike | D29: 120 | E29: =D29/$O$24 -> 0.0069847576 | F29: =D29*12 -> 1440 | G29: =F29/52 -> 27.692308 | I29: Gross Pay | J29: =J27*80 -> 4009.6 | L29: =J29*26 -> 104249.6 | M29: =L29/12 -> 8687.4667
A30: F | B30: 42 | C30: Water Bill - Main | D30: 75 | E30: =D30/$O$24 -> 0.0043654735 | F30: =D30*12 -> 900 | G30: =F30/52 -> 17.307692
A31: F | B31: 43 | C31: Water Bill - Rental | D31: 75 | E31: =D31/$O$24 -> 0.0043654735 | F31: =D31*12 -> 900 | G31: =F31/52 -> 17.307692 | I31: Health Ins | J31: 157.97 | K31: =J31/J29 -> 0.039397945 | L31: =J31*26 -> 4107.22 | M31: =L31/12 -> 342.26833
I32: TSP | J32: =K32*J29 -> 200.48 | K32: 0.05 | L32: =J32*26 -> 5212.48 | M32: =L32/12 -> 434.37333
A33: R | B33: 25 | C33: Vehicle Maintenance | D33: 350 | E33: =D33/$O$24 -> 0.02037221 | F33: =D33*12 -> 4200 | G33: =F33/52 -> 80.769231 | I33: Pre-Tax Deductions | J33: =SUM(J31:J32) -> 358.45
A34: R | B34: 26 | C34: Car Insurance | D34: 320 | E34: =D34/$O$24 -> 0.01862602 | F34: =D34*12 -> 3840 | G34: =F34/52 -> 73.846154
A35: R | B35: 27 | C35: Rental Garbage | D35: 25 | E35: =D35/$O$24 -> 0.0014551578 | F35: =D35*12 -> 300 | G35: =F35/52 -> 5.7692308 | I35: Taxable Pay | J35: =J29+J30-J31-J32 -> 3651.15 | K35: =J35/J29 -> 0.91060206 | L35: =J35*26 -> 94929.9 | M35: =L35/12 -> 7910.825
A36: R | B36: 28 | C36: Garbage | D36: 25 | E36: =D36/$O$24 -> 0.0014551578 | F36: =D36*12 -> 300 | G36: =F36/52 -> 5.7692308
A37: R | B37: 29 | C37: Sanitation - Main | D37: 45 | E37: =D37/$O$24 -> 0.0026192841 | F37: =D37*12 -> 540 | G37: =F37/52 -> 10.384615 | I37: Federal Tax | J37: 463.64 | K37: =J37/J35 -> 0.12698465 | L37: =J37*26 -> 12054.64 | M37: =L37/12 -> 1004.5533
A38: R | B38: 30 | C38: Camping/Vacation | D38: 400 | E38: =D38/$O$24 -> 0.023282525 | F38: =D38*12 -> 4800 | G38: =F38/52 -> 92.307692 | I38: Ohio Tax | J38: 97 | K38: =J38/J35 -> 0.026566972 | L38: =J38*26 -> 2522 | M38: =L38/12 -> 210.16667
A39: R | B39: 31 | C39: Home Maintenance | D39: 375 | E39: =D39/$O$24 -> 0.021827368 | F39: =D39*12 -> 4500 | G39: =F39/52 -> 86.538462 | I39: Medicare | J39: =(J35+J32)*K39 -> 55.848635 | K39: 0.0145 | L39: =J39*26 -> 1452.0645 | M39: =L39/12 -> 121.00538
A40: R | B40: 32 | C40: Rental Repairs | D40: 100 | E40: =D40/$O$24 -> 0.0058206314 | F40: =D40*12 -> 1200 | G40: =F40/52 -> 23.076923 | I40: Social Security | J40: =(J35+J32)*K40 -> 238.80106 | K40: 0.062 | L40: =J40*26 -> 6208.8276 | M40: =L40/12 -> 517.4023
A41: R | B41: 33 | C41: Rental Insurance | D41: 85 | E41: =D41/$O$24 -> 0.0049475367 | F41: =D41*12 -> 1020 | G41: =F41/52 -> 19.615385 | I41: FERS Retirement | J41: =K41*J29 -> 32.0768 | K41: 0.008 | L41: =J41*26 -> 833.9968 | M41: =L41/12 -> 69.499733
...

Sheet Monthly Breakdown
D1: Monthly | E1: Total | F1: Total | G1: % | H1: Monthly | I1: 46023 | J1: 46053 | K1: 46054 | L1: 46081 | M1: 46082 | N1: 46112 | O1: 46113 | P1: 46142 | Q1: 46143 | R1: 46173 | S1: 46174 | T1: 46203 | U1: 46204 | V1: 46234 | W1: 46235 | X1: 46265 | Y1: 46266 | Z1: 46295 | AA1: 46296 | AB1: 46326 | AC1: 45962 | AD1: 45991 | AE1: 45627 | AF1: 45657
D2: Average | E2: Spent | F2: Difference | G2: Under | H2: Budget | I2: Spent | J2: Difference | K2: Spent | L2: Difference | M2: Spent | N2: Difference | O2: Spent | Q2: Spent | R2: Difference | S2: Spent | T2: Difference | U2: Spent | V2: Difference | W2: Spent | X2: Difference | Y2: Spent | Z2: Difference | AA2: Spent | AB2: Difference | AC2: Spent | AD2: Difference | AE2: Spent | AF2: Difference
A3: ID | C3: TOTALS | E3: =SUM(E5:E46) -> 164107.11 | F3: =SUM(F5:F46) -> 7695.5584 | G3: =1-((E3/SUM(E3:F3))) -> 0.044793008 | H3: =SUM(H5:H67) -> 17180.267 | I3: =SUM(I5:I46) -> 15639.36 | K3: =SUM(K5:K46) -> 16615.62 | M3: =SUM(M5:M46) -> 16971.29 | O3: =SUM(O5:O46) -> 18875.67 | Q3: =SUM(Q5:Q46) -> 14973.2 | S3: =SUM(S5:S46) -> 17750.78 | U3: =SUM(U5:U46) -> 20061.94 | W3: =SUM(W5:W46) -> 17483.15 | Y3: =SUM(Y5:Y46) -> 14978.64 | AA3: =SUM(AA5:AA46) -> 10757.46 | AC3: =SUM(AC5:AC46) -> 0 | AE3: =SUM(AE5:AE46) -> 0
A4: SPEND ACCOUNT
A5: ='Proposed Budget'!A5 -> D | B5: ='Proposed Budget'!B5 -> 1 | C5: ='Proposed Budget'!C5 -> Groceries/Household | D5: =(E5/(TODAY()-$I$1))*30.42 -> 1079.3309 | E5: =I5+K5+M5+O5+Q5+S5+U5+W5+Y5+AA5+AC5+AE5 -> 10679.77 | F5: =J5+L5+N5+P5+R5+T5+V5+X5+Z5+AB5 -> 1320.23 | G5: =1-((E5/SUM(E5:F5))) -> 0.11001917 | H5: ='Proposed Budget'!D5 -> 1200 | I5: =SUMIFS('Checking Transaction Log'!$E:$E,'Checking Transaction Log'!$C:$C,">="&I1,'Checking Transaction Log'!$C:$C,"<="&J1,'Checking Transaction Log'!$A:$A,"D",'Checking Transaction Log'!$B:$B,1) -> 1067.56 | J5: =H5-I5 -> 132.44 | K5: =SUMIFS('Checking Transaction Log'!$E:$E,'Checking Transaction Log'!$C:$C,">="&K1,'Checking Transaction Log'!$C:$C,"<="&L1,'Checking Transaction Log'!$A:$A,"D",'Checking Transaction Log'!$B:$B,1) -> 1033.9 | L5: =H5-K5 -> 166.1 | M5: =SUMIFS('Checking Transaction Log'!$E:$E,'Checking Transaction Log'!$C:$C,">="&M1,'Checking Transaction Log'!$C:$C,"<="&N1,'Checking Transaction Log'!$A:$A,"D",'Checking Transaction Log'!$B:$B,1) -> 1358.86 | N5: =H5-M5 -> -158.86 | O5: =SUMIFS('Checking Transaction Log'!$E:$E,'Checking Transaction Log'!$C:$C,">="&O1,'Checking Transaction Log'!$C:$C,"<="&P1,'Checking Transaction Log'!$A:$A,"D",'Checking Transaction Log'!$B:$B,1) -> 1284.83 | P5: =H5-O5 -> -84.83 | Q5: =SUMIFS('Checking Transaction Log'!$E:$E,'Checking Transaction Log'!$C:$C,">="&Q1,'Checking Transaction Log'!$C:$C,"<="&R1,'Checking Transaction Log'!$A:$A,"D",'Checking Transaction Log'!$B:$B,1) -> 1263.15 | R5: =H5-Q5 -> -63.15 | S5: =SUMIFS('Checking Transaction Log'!$E:$E,'Checking Transaction Log'!$C:$C,">="&S1,'Checking Transaction Log'!$C:$C,"<="&T1,'Checking Transaction Log'!$A:$A,"D",'Checking Transaction Log'!$B:$B,1) -> 1292.96 | T5: =H5-S5 -> -92.96 | U5: =SUMIFS('Checking Transaction Log'!$E:$E,'Checking Transaction Log'!$C:$C,">="&U1,'Checking Transaction Log'!$C:$C,"<="&V1,'Checking Transaction Log'!$A:$A,"D",'Checking Transaction Log'!$B:$B,1) -> 1111.57 | V5: =H5-U5 -> 88.43 | W5: =SUMIFS('Checking Transaction Log'!$E:$E,'Checking Transaction Log'!$C:$C,">="&W1,'Checking Transaction Log'!$C:$C,"<="&X1,'Checking Transaction Log'!$A:$A,"D",'Checking Transaction Log'!$B:$B,1) -> 868.64 | X5: =H5-W5 -> 331.36 | Y5: =SUMIFS('Checking Transaction Log'!$E:$E,'Checking Transaction Log'!$C:$C,">="&Y1,'Checking Transaction Log'!$C:$C,"<="&Z1,'Checking Transaction Log'!$A:$A,"D",'Checking Transaction Log'!$B:$B,1) -> 451.57 | Z5: =H5-Y5 -> 748.43 | AA5: =SUMIFS('Checking Transaction Log'!$E:$E,'Checking Transaction Log'!$C:$C,">="&AA1,'Checking Transaction Log'!$C:$C,"<="&AB1,'Checking Transaction Log'!$A:$A,"D",'Checking Transaction Log'!$B:$B,1) -> 946.73 | AB5: =H5-AA5 -> 253.27 | AC5: =SUMIFS('Checking Transaction Log'!$E:$E,'Checking Transaction Log'!$C:$C,">="&AC1,'Checking Transaction Log'!$C:$C,"<="&AD1,'Checking Transaction Log'!$A:$A,"D",'Checking Transaction Log'!$B:$B,1) -> 0 | AD5: =H5-AC5 -> 1200 | AE5: =SUMIFS('Checking Transaction Log'!$E:$E,'Checking Transaction Log'!$C:$C,">="&AE1,'Checking Transaction Log'!$C:$C,"<="&AF1,'Checking Transaction Log'!$A:$A,"D",'Checking Transaction Log'!$B:$B,1) -> 0 | AF5: =H5-AE5 -> 1200
A6: ='Proposed Budget'!A6 -> D | B6: ='Proposed Budget'!B6 -> 2 | C6: ='Proposed Budget'!C6 -> Dining Out | D6: =(E6/(TODAY()-$I$1))*30.42 -> 1061.7813 | E6: =Q6+S6+U6+W6+Y6+AA6+AC6+AE6+I6+K6+M6+O6 -> 10506.12 | F6: =J6+L6+N6+P6+R6+T6+V6+X6+Z6+AB6 -> 1493.88 | G6: =1-((E6/SUM(E6:F6))) -> 0.12449 | H6: ='Proposed Budget'!D6 -> 1200 | I6: =SUMIFS('Checking Transaction Log'!E:E,'Checking Transaction Log'!C:C,">="&I1,'Checking Transaction Log'!C:C,"<="&J1,'Checking Transaction Log'!A:A,"D",'Checking Transaction Log'!B:B,2) -> 1061.45 | J6: =H6-I6 -> 138.55 | K6: =SUMIFS('Checking Transaction Log'!E:E,'Checking Transaction Log'!C:C,">="&K1,'Checking Transaction Log'!C:C,"<="&L1,'Checking Transaction Log'!A:A,"D",'Checking Transaction Log'!B:B,2) -> 911.68 | L6: =H6-K6 -> 288.32 | M6: =SUMIFS('Checking Transaction Log'!$E:$E,'Checking Transaction Log'!$C:$C,">="&M1,'Checking Transaction Log'!$C:$C,"<="&N1,'Checking Transaction Log'!$A:$A,"D",'Checking Transaction Log'!$B:$B,2) -> 1233.46 | N6: =H6-M6 -> -33.46 | O6: =SUMIFS('Checking Transaction Log'!$E:$E,'Checking Transaction Log'!$C:$C,">="&O1,'Checking Transaction Log'!$C:$C,"<="&P1,'Checking Transaction Log'!$A:$A,"D",'Checking Transaction Log'!$B:$B,2) -> 984.18 | P6: =H6-O6 -> 215.82 | Q6: =SUMIFS('Checking Transaction Log'!$E:$E,'Checking Transaction Log'!$C:$C,">="&Q1,'Checking Transaction Log'!$C:$C,"<="&R1,'Checking Transaction Log'!$A:$A,"D",'Checking Transaction Log'!$B:$B,2) -> 1603.86 | R6: =H6-Q6 -> -403.86 | S6: =SUMIFS('Checking Transaction Log'!$E:$E,'Checking Transaction Log'!$C:$C,">="&S1,'Checking Transaction Log'!$C:$C,"<="&T1,'Checking Transaction Log'!$A:$A,"D",'Checking Transaction Log'!$B:$B,2) -> 985.22 | T6: =H6-S6 -> 214.78 | U6: =SUMIFS('Checking Transaction Log'!$E:$E,'Checking Transaction Log'!$C:$C,">="&U1,'Checking Transaction Log'!$C:$C,"<="&V1,'Checking Transaction Log'!$A:$A,"D",'Checking Transaction Log'!$B:$B,2) -> 1129.6 | V6: =H6-U6 -> 70.4 | W6: =SUMIFS('Checking Transaction Log'!$E:$E,'Checking Transaction Log'!$C:$C,">="&W1,'Checking Transaction Log'!$C:$C,"<="&X1,'Checking Transaction Log'!$A:$A,"D",'Checking Transaction Log'!$B:$B,2) -> 816.74 | X6: =H6-W6 -> 383.26 | Y6: =SUMIFS('Checking Transaction Log'!$E:$E,'Checking Transaction Log'!$C:$C,">="&Y1,'Checking Transaction Log'!$C:$C,"<="&Z1,'Checking Transaction Log'!$A:$A,"D",'Checking Transaction Log'!$B:$B,2) -> 938.07 | Z6: =H6-Y6 -> 261.93 | AA6: =SUMIFS('Checking Transaction Log'!$E:$E,'Checking Transaction Log'!$C:$C,">="&AA1,'Checking Transaction Log'!$C:$C,"<="&AB1,'Checking Transaction Log'!$A:$A,"D",'Checking Transaction Log'!$B:$B,2) -> 841.86 | AB6: =H6-AA6 -> 358.14 | AC6: =SUMIFS('Checking Transaction Log'!$E:$E,'Checking Transaction Log'!$C:$C,">="&AC1,'Checking Transaction Log'!$C:$C,"<="&AD1,'Checking Transaction Log'!$A:$A,"D",'Checking Transaction Log'!$B:$B,2) -> 0 | AD6: =H6-AC6 -> 1200 | AE6: =SUMIFS('Checking Transaction Log'!$E:$E,'Checking Transaction Log'!$C:$C,">="&AE1,'Checking Transaction Log'!$C:$C,"<="&AF1,'Checking Transaction Log'!$A:$A,"D",'Checking Transaction Log'!$B:$B,2) -> 0 | AF6: =H6-AE6 -> 1200
A7: ='Proposed Budget'!A7 -> D | B7: ='Proposed Budget'!B7 -> 3 | C7: ='Proposed Budget'!C7 -> Misc Food | D7: =(E7/(TODAY()-$I$1))*30.42 -> 112.46001 | E7: =Q7+S7+U7+W7+Y7+AA7+AC7+AE7+I7+K7+M7+O7 -> 1112.77 | F7: =J7+L7+N7+P7+R7+T7+V7+X7+Z7+AB7 -> 387.23 | G7: =1-((E7/SUM(E7:F7))) -> 0.25815333 | H7: ='Proposed Budget'!D7 -> 150 | I7: =SUMIFS('Checking Transaction Log'!E:E,'Checking Transaction Log'!C:C,">="&I1,'Checking Transaction Log'!C:C,"<="&J1,'Checking Transaction Log'!A:A,"D",'Checking Transaction Log'!B:B,3) -> 144.51 | J7: =H7-I7 -> 5.49 | K7: =SUMIFS('Checking Transaction Log'!E:E,'Checking Transaction Log'!C:C,">="&K1,'Checking Transaction Log'!C:C,"<="&L1,'Checking Transaction Log'!A:A,"D",'Checking Transaction Log'!B:B,3) -> 90.76 | L7: =H7-K7 -> 59.24 | M7: =SUMIFS('Checking Transaction Log'!$E:$E,'Checking Transaction Log'!$C:$C,">="&M1,'Checking Transaction Log'!$C:$C,"<="&N1,'Checking Transaction Log'!$A:$A,"D",'Checking Transaction Log'!$B:$B,3) -> 173.53 | N7: =H7-M7 -> -23.53 | O7: =SUMIFS('Checking Transaction Log'!$E:$E,'Checking Transaction Log'!$C:$C,">="&O1,'Checking Transaction Log'!$C:$C,"<="&P1,'Checking Transaction Log'!$A:$A,"D",'Checking Transaction Log'!$B:$B,3) -> 91.66 | P7: =H7-O7 -> 58.34 | Q7: =SUMIFS('Checking Transaction Log'!$E:$E,'Checking Transaction Log'!$C:$C,">="&Q1,'Checking Transaction Log'!$C:$C,"<="&R1,'Checking Transaction Log'!$A:$A,"D",'Checking Transaction Log'!$B:$B,3) -> 180.06 | R7: =H7-Q7 -> -30.06 | S7: =SUMIFS('Checking Transaction Log'!$E:$E,'Checking Transaction Log'!$C:$C,">="&S1,'Checking Transaction Log'!$C:$C,"<="&T1,'Checking Transaction Log'!$A:$A,"D",'Checking Transaction Log'!$B:$B,3) -> 73.63 | T7: =H7-S7 -> 76.37 | U7: =SUMIFS('Checking Transaction Log'!$E:$E,'Checking Transaction Log'!$C:$C,">="&U1,'Checking Transaction Log'!$C:$C,"<="&V1,'Checking Transaction Log'!$A:$A,"D",'Checking Transaction Log'!$B:$B,3) -> 167.91 | V7: =H7-U7 -> -17.91 | W7: =SUMIFS('Checking Transaction Log'!$E:$E,'Checking Transaction Log'!$C:$C,">="&W1,'Checking Transaction Log'!$C:$C,"<="&X1,'Checking Transaction Log'!$A:$A,"D",'Checking Transaction Log'!$B:$B,3) -> 15.09 | X7: =H7-W7 -> 134.91 | Y7: =SUMIFS('Checking Transaction Log'!$E:$E,'Checking Transaction Log'!$C:$C,">="&Y1,'Checking Transaction Log'!$C:$C,"<="&Z1,'Checking Transaction Log'!$A:$A,"D",'Checking Transaction Log'!$B:$B,3) -> 110.24 | Z7: =H7-Y7 -> 39.76 | AA7: =SUMIFS('Checking Transaction Log'!$E:$E,'Checking Transaction Log'!$C:$C,">="&AA1,'Checking Transaction Log'!$C:$C,"<="&AB1,'Checking Transaction Log'!$A:$A,"D",'Checking Transaction Log'!$B:$B,3) -> 65.38 | AB7: =H7-AA7 -> 84.62 | AC7: =SUMIFS('Checking Transaction Log'!$E:$E,'Checking Transaction Log'!$C:$C,">="&AC1,'Checking Transaction Log'!$C:$C,"<="&AD1,'Checking Transaction Log'!$A:$A,"D",'Checking Transaction Log'!$B:$B,3) -> 0 | AD7: =H7-AC7 -> 150 | AE7: =SUMIFS('Checking Transaction Log'!$E:$E,'Checking Transaction Log'!$C:$C,">="&AE1,'Checking Transaction Log'!$C:$C,"<="&AF1,'Checking Transaction Log'!$A:$A,"D",'Checking Transaction Log'!$B:$B,3) -> 0 | AF7: =H7-AE7 -> 150
A8: ='Proposed Budget'!A8 -> D | B8: ='Proposed Budget'!B8 -> 4 | C8: ='Proposed Budget'!C8 -> Gasoline | D8: =(E8/(TODAY()-$I$1))*30.42 -> 648.42807 | E8: =Q8+S8+U8+W8+Y8+AA8+AC8+AE8+I8+K8+M8+O8 -> 6416.07 | F8: =J8+L8+N8+P8+R8+T8+V8+X8+Z8+AB8 -> -416.07 | G8: =1-((E8/SUM(E8:F8))) -> -0.069345 | H8: ='Proposed Budget'!D8 -> 600 | I8: =SUMIFS('Checking Transaction Log'!E:E,'Checking Transaction Log'!C:C,">="&I1,'Checking Transaction Log'!C:C,"<="&J1,'Checking Transaction Log'!A:A,"D",'Checking Transaction Log'!B:B,4) -> 561.41 | J8: =H8-I8 -> 38.59 | K8: =SUMIFS('Checking Transaction Log'!E:E,'Checking Transaction Log'!C:C,">="&K1,'Checking Transaction Log'!C:C,"<="&L1,'Checking Transaction Log'!A:A,"D",'Checking Transaction Log'!B:B,4) -> 710.78 | L8: =H8-K8 -> -110.78 | M8: =SUMIFS('Checking Transaction Log'!$E:$E,'Checking Transaction Log'!$C:$C,">="&M1,'Checking Transaction Log'!$C:$C,"<="&N1,'Checking Transaction Log'!$A:$A,"D",'Checking Transaction Log'!$B:$B,4) -> 537.41 | N8: =H8-M8 -> 62.59 | O8: =SUMIFS('Checking Transaction Log'!$E:$E,'Checking Transaction Log'!$C:$C,">="&O1,'Checking Transaction Log'!$C:$C,"<="&P1,'Checking Transaction Log'!$A:$A,"D",'Checking Transaction Log'!$B:$B,4) -> 592.33 | P8: =H8-O8 -> 7.67 | Q8: =SUMIFS('Checking Transaction Log'!$E:$E,'Checking Transaction Log'!$C:$C,">="&Q1,'Checking Transaction Log'!$C:$C,"<="&R1,'Checking Transaction Log'!$A:$A,"D",'Checking Transaction Log'!$B:$B,4) -> 942.96 | R8: =H8-Q8 -> -342.96 | S8: =SUMIFS('Checking Transaction Log'!$E:$E,'Checking Transaction Log'!$C:$C,">="&S1,'Checking Transaction Log'!$C:$C,"<="&T1,'Checking Transaction Log'!$A:$A,"D",'Checking Transaction Log'!$B:$B,4) -> 548.34 | T8: =H8-S8 -> 51.66 | U8: =SUMIFS('Checking Transaction Log'!$E:$E,'Checking Transaction Log'!$C:$C,">="&U1,'Checking Transaction Log'!$C:$C,"<="&V1,'Checking Transaction Log'!$A:$A,"D",'Checking Transaction Log'!$B:$B,4) -> 604.87 | V8: =H8-U8 -> -4.87 | W8: =SUMIFS('Checking Transaction Log'!$E:$E,'Checking Transaction Log'!$C:$C,">="&W1,'Checking Transaction Log'!$C:$C,"<="&X1,'Checking Transaction Log'!$A:$A,"D",'Checking Transaction Log'!$B:$B,4) -> 475.49 | X8: =H8-W8 -> 124.51 | Y8: =SUMIFS('Checking Transaction Log'!$E:$E,'Checking Transaction Log'!$C:$C,">="&Y1,'Checking Transaction Log'!$C:$C,"<="&Z1,'Checking Transaction Log'!$A:$A,"D",'Checking Transaction Log'!$B:$B,4) -> 770.33 | Z8: =H8-Y8 -> -170.33 | AA8: =SUMIFS('Checking Transaction Log'!$E:$E,'Checking Transaction Log'!$C:$C,">="&AA1,'Checking Transaction Log'!$C:$C,"<="&AB1,'Checking Transaction Log'!$A:$A,"D",'Checking Transaction Log'!$B:$B,4) -> 672.15 | AB8: =H8-AA8 -> -72.15 | AC8: =SUMIFS('Checking Transaction Log'!$E:$E,'Checking Transaction Log'!$C:$C,">="&AC1,'Checking Transaction Log'!$C:$C,"<="&AD1,'Checking Transaction Log'!$A:$A,"D",'Checking Transaction Log'!$B:$B,4) -> 0 | AD8: =H8-AC8 -> 600 | AE8: =SUMIFS('Checking Transaction Log'!$E:$E,'Checking Transaction Log'!$C:$C,">="&AE1,'Checking Transaction Log'!$C:$C,"<="&AF1,'Checking Transaction Log'!$A:$A,"D",'Checking Transaction Log'!$B:$B,4) -> 0 | AF8: =H8-AE8 -> 600
A9: ='Proposed Budget'!A9 -> D | B9: ='Proposed Budget'!B9 -> 5 | C9: ='Proposed Budget'!C9 -> Family Entertainment | D9: =(E9/(TODAY()-$I$1))*30.42 -> 809.43173 | E9: =Q9+S9+U9+W9+Y9+AA9+AC9+AE9+I9+K9+M9+O9 -> 8009.17 | F9: =J9+L9+N9+P9+R9+T9+V9+X9+Z9+AB9 -> -1009.17 | G9: =1-((E9/SUM(E9:F9))) -> -0.14416714 | H9: ='Proposed Budget'!D9 -> 700 | I9: =SUMIFS('Checking Transaction Log'!E:E,'Checking Transaction Log'!C:C,">="&I1,'Checking Transaction Log'!C:C,"<="&J1,'Checking Transaction Log'!A:A,"D",'Checking Transaction Log'!B:B,5) -> 717.1 | J9: =H9-I9 -> -17.1 | K9: =SUMIFS('Checking Transaction Log'!E:E,'Checking Transaction Log'!C:C,">="&K1,'Checking Transaction Log'!C:C,"<="&L1,'Checking Transaction Log'!A:A,"D",'Checking Transaction Log'!B:B,5) -> 780.14 | L9: =H9-K9 -> -80.14 | M9: =SUMIFS('Checking Transaction Log'!$E:$E,'Checking Transaction Log'!$C:$C,">="&M1,'Checking Transaction Log'!$C:$C,"<="&N1,'Checking Transaction Log'!$A:$A,"D",'Checking Transaction Log'!$B:$B,5) -> 516.79 | N9: =H9-M9 -> 183.21 | O9: =SUMIFS('Checking Transaction Log'!$E:$E,'Checking Transaction Log'!$C:$C,">="&O1,'Checking Transaction Log'!$C:$C,"<="&P1,'Checking Transaction Log'!$A:$A,"D",'Checking Transaction Log'!$B:$B,5) -> 1673.98 | P9: =H9-O9 -> -973.98 | Q9: =SUMIFS('Checking Transaction Log'!$E:$E,'Checking Transaction Log'!$C:$C,">="&Q1,'Checking Transaction Log'!$C:$C,"<="&R1,'Checking Transaction Log'!$A:$A,"D",'Checking Transaction Log'!$B:$B,5) -> 310.77 | R9: =H9-Q9 -> 389.23 | S9: =SUMIFS('Checking Transaction Log'!$E:$E,'Checking Transaction Log'!$C:$C,">="&S1,'Checking Transaction Log'!$C:$C,"<="&T1,'Checking Transaction Log'!$A:$A,"D",'Checking Transaction Log'!$B:$B,5) -> 236.03 | T9: =H9-S9 -> 463.97 | U9: =SUMIFS('Checking Transaction Log'!$E:$E,'Checking Transaction Log'!$C:$C,">="&U1,'Checking Transaction Log'!$C:$C,"<="&V1,'Checking Transaction Log'!$A:$A,"D",'Checking Transaction Log'!$B:$B,5) -> 530.84 | V9: =H9-U9 -> 169.16 | W9: =SUMIFS('Checking Transaction Log'!$E:$E,'Checking Transaction Log'!$C:$C,">="&W1,'Checking Transaction Log'!$C:$C,"<="&X1,'Checking Transaction Log'!$A:$A,"D",'Checking Transaction Log'!$B:$B,5) -> 377.12 | X9: =H9-W9 -> 322.88 | Y9: =SUMIFS('Checking Transaction Log'!$E:$E,'Checking Transaction Log'!$C:$C,">="&Y1,'Checking Transaction Log'!$C:$C,"<="&Z1,'Checking Transaction Log'!$A:$A,"D",'Checking Transaction Log'!$B:$B,5) -> 1921.67 | Z9: =H9-Y9 -> -1221.67 | AA9: =SUMIFS('Checking Transaction Log'!$E:$E,'Checking Transaction Log'!$C:$C,">="&AA1,'Checking Transaction Log'!$C:$C,"<="&AB1,'Checking Transaction Log'!$A:$A,"D",'Checking Transaction Log'!$B:$B,5) -> 944.73 | AB9: =H9-AA9 -> -244.73 | AC9: =SUMIFS('Checking Transaction Log'!$E:$E,'Checking Transaction Log'!$C:$C,">="&AC1,'Checking Transaction Log'!$C:$C,"<="&AD1,'Checking Transaction Log'!$A:$A,"D",'Checking Transaction Log'!$B:$B,5) -> 0 | AD9: =H9-AC9 -> 700 | AE9: =SUMIFS('Checking Transaction Log'!$E:$E,'Checking Transaction Log'!$C:$C,">="&AE1,'Checking Transaction Log'!$C:$C,"<="&AF1,'Checking Transaction Log'!$A:$A,"D",'Checking Transaction Log'!$B:$B,5) -> 0 | AF9: =H9-AE9 -> 700
A10: ='Proposed Budget'!A10 -> D | B10: ='Proposed Budget'!B10 -> 6 | C10: ='Proposed Budget'!C10 -> Miscellaneous Spending | D10: =(E10/(TODAY()-$I$1))*30.42 -> 858.60298 | E10: =Q10+S10+U10+W10+Y10+AA10+AC10+AE10+I10+K10+M10+O10 -> 8495.71 | F10: =J10+L10+N10+P10+R10+T10+V10+X10+Z10+AB10 -> 504.29 | G10: =1-((E10/SUM(E10:F10))) -> 0.056032222 | H10: ='Proposed Budget'!D10 -> 900 | I10: =SUMIFS('Checking Transaction Log'!E:E,'Checking Transaction Log'!C:C,">="&I1,'Checking Transaction Log'!C:C,"<="&J1,'Checking Transaction Log'!A:A,"D",'Checking Transaction Log'!B:B,6) -> 714.12 | J10: =H10-I10 -> 185.88 | K10: =SUMIFS('Checking Transaction Log'!E:E,'Checking Transaction Log'!C:C,">="&K1,'Checking Transaction Log'!C:C,"<="&L1,'Checking Transaction Log'!A:A,"D",'Checking Transaction Log'!B:B,6) -> 693.08 | L10: =H10-K10 -> 206.92 | M10: =SUMIFS('Checking Transaction Log'!$E:$E,'Checking Transaction Log'!$C:$C,">="&M1,'Checking Transaction Log'!$C:$C,"<="&N1,'Checking Transaction Log'!$A:$A,"D",'Checking Transaction Log'!$B:$B,6) -> 484.7 | N10: =H10-M10 -> 415.3 | O10: =SUMIFS('Checking Transaction Log'!$E:$E,'Checking Transaction Log'!$C:$C,">="&O1,'Checking Transaction Log'!$C:$C,"<="&P1,'Checking Transaction Log'!$A:$A,"D",'Checking Transaction Log'!$B:$B,6) -> 1146.79 | P10: =H10-O10 -> -246.79 | Q10: =SUMIFS('Checking Transaction Log'!$E:$E,'Checking Transaction Log'!$C:$C,">="&Q1,'Checking Transaction Log'!$C:$C,"<="&R1,'Checking Transaction Log'!$A:$A,"D",'Checking Transaction Log'!$B:$B,6) -> 1049.97 | R10: =H10-Q10 -> -149.97 | S10: =SUMIFS('Checking Transaction Log'!$E:$E,'Checking Transaction Log'!$C:$C,">="&S1,'Checking Transaction Log'!$C:$C,"<="&T1,'Checking Transaction Log'!$A:$A,"D",'Checking Transaction Log'!$B:$B,6) -> 717.77 | T10: =H10-S10 -> 182.23 | U10: =SUMIFS('Checking Transaction Log'!$E:$E,'Checking Transaction Log'!$C:$C,">="&U1,'Checking Transaction Log'!$C:$C,"<="&V1,'Checking Transaction Log'!$A:$A,"D",'Checking Transaction Log'!$B:$B,6) -> 707.58 | V10: =H10-U10 -> 192.42 | W10: =SUMIFS('Checking Transaction Log'!$E:$E,'Checking Transaction Log'!$C:$C,">="&W1,'Checking Transaction Log'!$C:$C,"<="&X1,'Checking Transaction Log'!$A:$A,"D",'Checking Transaction Log'!$B:$B,6) -> 777.34 | X10: =H10-W10 -> 122.66 | Y10: =SUMIFS('Checking Transaction Log'!$E:$E,'Checking Transaction Log'!$C:$C,">="&Y1,'Checking Transaction Log'!$C:$C,"<="&Z1,'Checking Transaction Log'!$A:$A,"D",'Checking Transaction Log'!$B:$B,6) -> 1024.61 | Z10: =H10-Y10 -> -124.61 | AA10: =SUMIFS('Checking Transaction Log'!$E:$E,'Checking Transaction Log'!$C:$C,">="&AA1,'Checking Transaction Log'!$C:$C,"<="&AB1,'Checking Transaction Log'!$A:$A,"D",'Checking Transaction Log'!$B:$B,6) -> 1179.75 | AB10: =H10-AA10 -> -279.75 | AC10: =SUMIFS('Checking Transaction Log'!$E:$E,'Checking Transaction Log'!$C:$C,">="&AC1,'Checking Transaction Log'!$C:$C,"<="&AD1,'Checking Transaction Log'!$A:$A,"D",'Checking Transaction Log'!$B:$B,6) -> 0 | AD10: =H10-AC10 -> 900 | AE10: =SUMIFS('Checking Transaction Log'!$E:$E,'Checking Transaction Log'!$C:$C,">="&AE1,'Checking Transaction Log'!$C:$C,"<="&AF1,'Checking Transaction Log'!$A:$A,"D",'Checking Transaction Log'!$B:$B,6) -> 0 | AF10: =H10-AE10 -> 900
A11: ='Proposed Budget'!A11 -> D | B11: ='Proposed Budget'!B11 -> 7 | C11: ='Proposed Budget'!C11 -> Department Stores/Clothes | D11: =(E11/(TODAY()-$I$1))*30.42 -> 294.20991 | E11: =Q11+S11+U11+W11+Y11+AA11+AC11+AE11+I11+K11+M11+O11 -> 2911.15 | F11: =J11+L11+N11+P11+R11+T11+V11+X11+Z11+AB11 -> 588.85 | G11: =1-((E11/SUM(E11:F11))) -> 0.16824286 | H11: ='Proposed Budget'!D11 -> 350 | I11: =SUMIFS('Checking Transaction Log'!E:E,'Checking Transaction Log'!C:C,">="&I1,'Checking Transaction Log'!C:C,"<="&J1,'Checking Transaction Log'!A:A,"D",'Checking Transaction Log'!B:B,7) -> 626.04 | J11: =H11-I11 -> -276.04 | K11: =SUMIFS('Checking Transaction Log'!E:E,'Checking Transaction Log'!C:C,">="&K1,'Checking Transaction Log'!C:C,"<="&L1,'Checking Transaction Log'!A:A,"D",'Checking Transaction Log'!B:B,7) -> 670.18 | L11: =H11-K11 -> -320.18 | M11: =SUMIFS('Checking Transaction Log'!$E:$E,'Checking Transaction Log'!$C:$C,">="&M1,'Checking Transaction Log'!$C:$C,"<="&N1,'Checking Transaction Log'!$A:$A,"D",'Checking Transaction Log'!$B:$B,7) -> 221.65 | N11: =H11-M11 -> 128.35 | O11: =SUMIFS('Checking Transaction Log'!$E:$E,'Checking Transaction Log'!$C:$C,">="&O1,'Checking Transaction Log'!$C:$C,"<="&P1,'Checking Transaction Log'!$A:$A,"D",'Checking Transaction Log'!$B:$B,7) -> 269.88 | P11: =H11-O11 -> 80.12 | Q11: =SUMIFS('Checking Transaction Log'!$E:$E,'Checking Transaction Log'!$C:$C,">="&Q1,'Checking Transaction Log'!$C:$C,"<="&R1,'Checking Transaction Log'!$A:$A,"D",'Checking Transaction Log'!$B:$B,7) -> 376.41 | R11: =H11-Q11 -> -26.41 | S11: =SUMIFS('Checking Transaction Log'!$E:$E,'Checking Transaction Log'!$C:$C,">="&S1,'Checking Transaction Log'!$C:$C,"<="&T1,'Checking Transaction Log'!$A:$A,"D",'Checking Transaction Log'!$B:$B,7) -> 0 | T11: =H11-S11 -> 350 | U11: =SUMIFS('Checking Transaction Log'!$E:$E,'Checking Transaction Log'!$C:$C,">="&U1,'Checking Transaction Log'!$C:$C,"<="&V1,'Checking Transaction Log'!$A:$A,"D",'Checking Transaction Log'!$B:$B,7) -> 0 | V11: =H11-U11 -> 350 | W11: =SUMIFS('Checking Transaction Log'!$E:$E,'Checking Transaction Log'!$C:$C,">="&W1,'Checking Transaction Log'!$C:$C,"<="&X1,'Checking Transaction Log'!$A:$A,"D",'Checking Transaction Log'!$B:$B,7) -> 374.35 | X11: =H11-W11 -> -24.35 | Y11: =SUMIFS('Checking Transaction Log'!$E:$E,'Checking Transaction Log'!$C:$C,">="&Y1,'Checking Transaction Log'!$C:$C,"<="&Z1,'Checking Transaction Log'!$A:$A,"D",'Checking Transaction Log'!$B:$B,7) -> 252.08 | Z11: =H11-Y11 -> 97.92 | AA11: =SUMIFS('Checking Transaction Log'!$E:$E,'Checking Transaction Log'!$C:$C,">="&AA1,'Checking Transaction Log'!$C:$C,"<="&AB1,'Checking Transaction Log'!$A:$A,"D",'Checking Transaction Log'!$B:$B,7) -> 120.56 | AB11: =H11-AA11 -> 229.44 | AC11: =SUMIFS('Checking Transaction Log'!$E:$E,'Checking Transaction Log'!$C:$C,">="&AC1,'Checking Transaction Log'!$C:$C,"<="&AD1,'Checking Transaction Log'!$A:$A,"D",'Checking Transaction Log'!$B:$B,7) -> 0 | AD11: =H11-AC11 -> 350 | AE11: =SUMIFS('Checking Transaction Log'!$E:$E,'Checking Transaction Log'!$C:$C,">="&AE1,'Checking Transaction Log'!$C:$C,"<="&AF1,'Checking Transaction Log'!$A:$A,"D",'Checking Transaction Log'!$B:$B,7) -> 0 | AF11: =H11-AE11 -> 350
A12: ='Proposed Budget'!A12 -> D | B12: ='Proposed Budget'!B12 -> 8 | C12: ='Proposed Budget'!C12 -> Alcohol/Bars | D12: =(E12/(TODAY()-$I$1))*30.42 -> 742.56837 | E12: =Q12+S12+U12+W12+Y12+AA12+AC12+AE12+I12+K12+M12+O12 -> 7347.57 | F12: =J12+L12+N12+P12+R12+T12+V12+X12+Z12+AB12 -> -347.57 | G12: =1-((E12/SUM(E12:F12))) -> -0.049652857 | H12: ='Proposed Budget'!D12 -> 700 | I12: =SUMIFS('Checking Transaction Log'!E:E,'Checking Transaction Log'!C:C,">="&I1,'Checking Transaction Log'!C:C,"<="&J1,'Checking Transaction Log'!A:A,"D",'Checking Transaction Log'!B:B,8) -> 683.49 | J12: =H12-I12 -> 16.51 | K12: =SUMIFS('Checking Transaction Log'!E:E,'Checking Transaction Log'!C:C,">="&K1,'Checking Transaction Log'!C:C,"<="&L1,'Checking Transaction Log'!A:A,"D",'Checking Transaction Log'!B:B,8) -> 979.71 | L12: =H12-K12 -> -279.71 | M12: =SUMIFS('Checking Transaction Log'!$E:$E,'Checking Transaction Log'!$C:$C,">="&M1,'Checking Transaction Log'!$C:$C,"<="&N1,'Checking Transaction Log'!$A:$A,"D",'Checking Transaction Log'!$B:$B,8) -> 640.42 | N12: =H12-M12 -> 59.58 | O12: =SUMIFS('Checking Transaction Log'!$E:$E,'Checking Transaction Log'!$C:$C,">="&O1,'Checking Transaction Log'!$C:$C,"<="&P1,'Checking Transaction Log'!$A:$A,"D",'Checking Transaction Log'!$B:$B,8) -> 654.01 | P12: =H12-O12 -> 45.99 | Q12: =SUMIFS('Checking Transaction Log'!$E:$E,'Checking Transaction Log'!$C:$C,">="&Q1,'Checking Transaction Log'!$C:$C,"<="&R1,'Checking Transaction Log'!$A:$A,"D",'Checking Transaction Log'!$B:$B,8) -> 972.26 | R12: =H12-Q12 -> -272.26 | S12: =SUMIFS('Checking Transaction Log'!$E:$E,'Checking Transaction Log'!$C:$C,">="&S1,'Checking Transaction Log'!$C:$C,"<="&T1,'Checking Transaction Log'!$A:$A,"D",'Checking Transaction Log'!$B:$B,8) -> 617.53 | T12: =H12-S12 -> 82.47 | U12: =SUMIFS('Checking Transaction Log'!$E:$E,'Checking Transaction Log'!$C:$C,">="&U1,'Checking Transaction Log'!$C:$C,"<="&V1,'Checking Transaction Log'!$A:$A,"D",'Checking Transaction Log'!$B:$B,8) -> 925.98 | V12: =H12-U12 -> -225.98 | W12: =SUMIFS('Checking Transaction Log'!$E:$E,'Checking Transaction Log'!$C:$C,">="&W1,'Checking Transaction Log'!$C:$C,"<="&X1,'Checking Transaction Log'!$A:$A,"D",'Checking Transaction Log'!$B:$B,8) -> 796.96 | X12: =H12-W12 -> -96.96 | Y12: =SUMIFS('Checking Transaction Log'!$E:$E,'Checking Transaction Log'!$C:$C,">="&Y1,'Checking Transaction Log'!$C:$C,"<="&Z1,'Checking Transaction Log'!$A:$A,"D",'Checking Transaction Log'!$B:$B,8) -> 464.71 | Z12: =H12-Y12 -> 235.29 | AA12: =SUMIFS('Checking Transaction Log'!$E:$E,'Checking Transaction Log'!$C:$C,">="&AA1,'Checking Transaction Log'!$C:$C,"<="&AB1,'Checking Transaction Log'!$A:$A,"D",'Checking Transaction Log'!$B:$B,8) -> 612.5 | AB12: =H12-AA12 -> 87.5 | AC12: =SUMIFS('Checking Transaction Log'!$E:$E,'Checking Transaction Log'!$C:$C,">="&AC1,'Checking Transaction Log'!$C:$C,"<="&AD1,'Checking Transaction Log'!$A:$A,"D",'Checking Transaction Log'!$B:$B,8) -> 0 | AD12: =H12-AC12 -> 700 | AE12: =SUMIFS('Checking Transaction Log'!$E:$E,'Checking Transaction Log'!$C:$C,">="&AE1,'Checking Transaction Log'!$C:$C,"<="&AF1,'Checking Transaction Log'!$A:$A,"D",'Checking Transaction Log'!$B:$B,8) -> 0 | AF12: =H12-AE12 -> 700
A14: ='Proposed Budget'!A14 -> F | B14: ='Proposed Budget'!B14 -> 9 | C14: ='Proposed Budget'!C14 -> Rocket Mortgage | D14: =(E14/(TODAY()-$I$1))*30.42 -> 1264.9263 | E14: =Q14+S14+U14+W14+Y14+AA14+AC14+AE14+I14+K14+M14+O14 -> 12516.2 | F14: =J14+L14+N14+P14+R14+T14+V14+X14+Z14+AB14 -> 333.8 | G14: =1-((E14/SUM(E14:F14))) -> 0.025976654 | H14: ='Proposed Budget'!D14 -> 1285 | I14: =SUMIFS('Checking Transaction Log'!E:E,'Checking Transaction Log'!C:C,">="&I1,'Checking Transaction Log'!C:C,"<="&J1,'Checking Transaction Log'!A:A,"F",'Checking Transaction Log'!B:B,9) -> 1281.53 | J14: =H14-I14 -> 3.47 | K14: =SUMIFS('Checking Transaction Log'!E:E,'Checking Transaction Log'!C:C,">="&K1,'Checking Transaction Log'!C:C,"<="&L1,'Checking Transaction Log'!A:A,"F",'Checking Transaction Log'!B:B,9) -> 1281.53 | L14: =H14-K14 -> 3.47 | M14: =SUMIFS('Checking Transaction Log'!$E:$E,'Checking Transaction Log'!$C:$C,">="&M1,'Checking Transaction Log'!$C:$C,"<="&N1,'Checking Transaction Log'!$A:$A,"F",'Checking Transaction Log'!$B:$B,9) -> 1281.53 | N14: =H14-M14 -> 3.47 | O14: =SUMIFS('Checking Transaction Log'!$E:$E,'Checking Transaction Log'!$C:$C,">="&O1,'Checking Transaction Log'!$C:$C,"<="&P1,'Checking Transaction Log'!$A:$A,"F",'Checking Transaction Log'!$B:$B,9) -> 1281.53 | P14: =H14-O14 -> 3.47 | Q14: =SUMIFS('Checking Transaction Log'!$E:$E,'Checking Transaction Log'!$C:$C,">="&Q1,'Checking Transaction Log'!$C:$C,"<="&R1,'Checking Transaction Log'!$A:$A,"F",'Checking Transaction Log'!$B:$B,9) -> 1231.68 | R14: =H14-Q14 -> 53.32 | S14: =SUMIFS('Checking Transaction Log'!$E:$E,'Checking Transaction Log'!$C:$C,">="&S1,'Checking Transaction Log'!$C:$C,"<="&T1,'Checking Transaction Log'!$A:$A,"F",'Checking Transaction Log'!$B:$B,9) -> 1231.68 | T14: =H14-S14 -> 53.32 | U14: =SUMIFS('Checking Transaction Log'!$E:$E,'Checking Transaction Log'!$C:$C,">="&U1,'Checking Transaction Log'!$C:$C,"<="&V1,'Checking Transaction Log'!$A:$A,"F",'Checking Transaction Log'!$B:$B,9) -> 1231.68 | V14: =H14-U14 -> 53.32 | W14: =SUMIFS('Checking Transaction Log'!$E:$E,'Checking Transaction Log'!$C:$C,">="&W1,'Checking Transaction Log'!$C:$C,"<="&X1,'Checking Transaction Log'!$A:$A,"F",'Checking Transaction Log'!$B:$B,9) -> 1231.68 | X14: =H14-W14 -> 53.32 | Y14: =SUMIFS('Checking Transaction Log'!$E:$E,'Checking Transaction Log'!$C:$C,">="&Y1,'Checking Transaction Log'!$C:$C,"<="&Z1,'Checking Transaction Log'!$A:$A,"F",'Checking Transaction Log'!$B:$B,9) -> 1231.68 | Z14: =H14-Y14 -> 53.32 | AA14: =SUMIFS('Checking Transaction Log'!$E:$E,'Checking Transaction Log'!$C:$C,">="&AA1,'Checking Transaction Log'!$C:$C,"<="&AB1,'Checking Transaction Log'!$A:$A,"F",'Checking Transaction Log'!$B:$B,9) -> 1231.68 | AB14: =H14-AA14 -> 53.32 | AC14: =SUMIFS('Checking Transaction Log'!$E:$E,'Checking Transaction Log'!$C:$C,">="&AC1,'Checking Transaction Log'!$C:$C,"<="&AD1,'Checking Transaction Log'!$A:$A,"F",'Checking Transaction Log'!$B:$B,9) -> 0 | AD14: =H14-AC14 -> 1285 | AE14: =SUMIFS('Checking Transaction Log'!$E:$E,'Checking Transaction Log'!$C:$C,">="&AE1,'Checking Transaction Log'!$C:$C,"<="&AF1,'Checking Transaction Log'!$A:$A,"F",'Checking Transaction Log'!$B:$B,9) -> 0 | AF14: =H14-AE14 -> 1285
